[2024-04-16T10:29:40.228+0000] {local_task_job_runner.py:120} INFO - ::group::Pre task execution logs
[2024-04-16T10:29:40.381+0000] {taskinstance.py:2073} INFO - Dependencies all met for dep_context=non-requeueable deps ti=<TaskInstance: priority_one_number_one_dag_v1.task_4 scheduled__2024-04-13T00:00:00+00:00 [queued]>
[2024-04-16T10:29:40.430+0000] {taskinstance.py:2073} INFO - Dependencies all met for dep_context=requeueable deps ti=<TaskInstance: priority_one_number_one_dag_v1.task_4 scheduled__2024-04-13T00:00:00+00:00 [queued]>
[2024-04-16T10:29:40.436+0000] {taskinstance.py:2303} INFO - Starting attempt 3 of 6
[2024-04-16T10:29:40.726+0000] {taskinstance.py:2327} INFO - Executing <Task(BashOperator): task_4> on 2024-04-13 00:00:00+00:00
[2024-04-16T10:29:40.792+0000] {warnings.py:110} WARNING - /home/***/.local/lib/python3.12/site-packages/***/task/task_runner/standard_task_runner.py:61: DeprecationWarning: This process (pid=347) is multi-threaded, use of fork() may lead to deadlocks in the child.
  pid = os.fork()

[2024-04-16T10:29:40.805+0000] {standard_task_runner.py:63} INFO - Started process 356 to run task
[2024-04-16T10:29:40.916+0000] {standard_task_runner.py:90} INFO - Running: ['***', 'tasks', 'run', 'priority_one_number_one_dag_v1', 'task_4', 'scheduled__2024-04-13T00:00:00+00:00', '--job-id', '265', '--raw', '--subdir', 'DAGS_FOLDER/priority_one_number_one_dag.py', '--cfg-path', '/tmp/tmp6jdfcn8i']
[2024-04-16T10:29:40.977+0000] {standard_task_runner.py:91} INFO - Job 265: Subtask task_4
[2024-04-16T10:29:41.742+0000] {task_command.py:426} INFO - Running <TaskInstance: priority_one_number_one_dag_v1.task_4 scheduled__2024-04-13T00:00:00+00:00 [running]> on host eaff2d74d54d
[2024-04-16T10:29:42.139+0000] {taskinstance.py:2644} INFO - Exporting env vars: AIRFLOW_CTX_DAG_OWNER='ika' AIRFLOW_CTX_DAG_ID='priority_one_number_one_dag_v1' AIRFLOW_CTX_TASK_ID='task_4' AIRFLOW_CTX_EXECUTION_DATE='2024-04-13T00:00:00+00:00' AIRFLOW_CTX_TRY_NUMBER='3' AIRFLOW_CTX_DAG_RUN_ID='scheduled__2024-04-13T00:00:00+00:00'
[2024-04-16T10:29:42.148+0000] {taskinstance.py:430} INFO - ::endgroup::
[2024-04-16T10:29:42.223+0000] {subprocess.py:63} INFO - Tmp dir root location: /tmp
[2024-04-16T10:29:42.236+0000] {subprocess.py:75} INFO - Running command: ['/usr/bin/bash', '-c', 'touch about_us/about.txt']
[2024-04-16T10:29:42.277+0000] {subprocess.py:86} INFO - Output:
[2024-04-16T10:29:42.293+0000] {subprocess.py:93} INFO - touch: cannot touch 'about_us/about.txt': No such file or directory
[2024-04-16T10:29:42.295+0000] {subprocess.py:97} INFO - Command exited with return code 1
[2024-04-16T10:29:42.300+0000] {taskinstance.py:441} INFO - ::group::Post task execution logs
[2024-04-16T10:29:42.371+0000] {taskinstance.py:2890} ERROR - Task failed with exception
Traceback (most recent call last):
  File "/home/airflow/.local/lib/python3.12/site-packages/airflow/models/taskinstance.py", line 465, in _execute_task
    result = _execute_callable(context=context, **execute_callable_kwargs)
             ^^^^^^^^^^^^^^^^^^^^^^^^^^^^^^^^^^^^^^^^^^^^^^^^^^^^^^^^^^^^^
  File "/home/airflow/.local/lib/python3.12/site-packages/airflow/models/taskinstance.py", line 432, in _execute_callable
    return execute_callable(context=context, **execute_callable_kwargs)
           ^^^^^^^^^^^^^^^^^^^^^^^^^^^^^^^^^^^^^^^^^^^^^^^^^^^^^^^^^^^^
  File "/home/airflow/.local/lib/python3.12/site-packages/airflow/models/baseoperator.py", line 400, in wrapper
    return func(self, *args, **kwargs)
           ^^^^^^^^^^^^^^^^^^^^^^^^^^^
  File "/home/airflow/.local/lib/python3.12/site-packages/airflow/operators/bash.py", line 243, in execute
    raise AirflowException(
airflow.exceptions.AirflowException: Bash command failed. The command returned a non-zero exit code 1.
[2024-04-16T10:29:42.404+0000] {taskinstance.py:1205} INFO - Marking task as UP_FOR_RETRY. dag_id=priority_one_number_one_dag_v1, task_id=task_4, execution_date=20240413T000000, start_date=20240416T102940, end_date=20240416T102942
[2024-04-16T10:29:42.458+0000] {standard_task_runner.py:110} ERROR - Failed to execute job 265 for task task_4 (Bash command failed. The command returned a non-zero exit code 1.; 356)
[2024-04-16T10:29:42.496+0000] {local_task_job_runner.py:240} INFO - Task exited with return code 1
[2024-04-16T10:29:42.573+0000] {taskinstance.py:3482} INFO - 0 downstream tasks scheduled from follow-on schedule check
[2024-04-16T10:29:42.579+0000] {local_task_job_runner.py:222} INFO - ::endgroup::
