[2024-04-16T10:25:12.375+0000] {local_task_job_runner.py:120} INFO - ::group::Pre task execution logs
[2024-04-16T10:25:12.405+0000] {taskinstance.py:2073} INFO - Dependencies all met for dep_context=non-requeueable deps ti=<TaskInstance: priority_one_number_one_dag_v1.task_5 scheduled__2024-04-11T00:00:00+00:00 [queued]>
[2024-04-16T10:25:12.414+0000] {taskinstance.py:2073} INFO - Dependencies all met for dep_context=requeueable deps ti=<TaskInstance: priority_one_number_one_dag_v1.task_5 scheduled__2024-04-11T00:00:00+00:00 [queued]>
[2024-04-16T10:25:12.415+0000] {taskinstance.py:2303} INFO - Starting attempt 2 of 6
[2024-04-16T10:25:12.445+0000] {taskinstance.py:2327} INFO - Executing <Task(BashOperator): task_5> on 2024-04-11 00:00:00+00:00
[2024-04-16T10:25:12.458+0000] {warnings.py:110} WARNING - /home/***/.local/lib/python3.12/site-packages/***/task/task_runner/standard_task_runner.py:61: DeprecationWarning: This process (pid=195) is multi-threaded, use of fork() may lead to deadlocks in the child.
  pid = os.fork()

[2024-04-16T10:25:12.460+0000] {standard_task_runner.py:63} INFO - Started process 196 to run task
[2024-04-16T10:25:12.459+0000] {standard_task_runner.py:90} INFO - Running: ['***', 'tasks', 'run', 'priority_one_number_one_dag_v1', 'task_5', 'scheduled__2024-04-11T00:00:00+00:00', '--job-id', '229', '--raw', '--subdir', 'DAGS_FOLDER/priority_one_number_one_dag.py', '--cfg-path', '/tmp/tmpz2u__ug4']
[2024-04-16T10:25:12.462+0000] {standard_task_runner.py:91} INFO - Job 229: Subtask task_5
[2024-04-16T10:25:12.547+0000] {task_command.py:426} INFO - Running <TaskInstance: priority_one_number_one_dag_v1.task_5 scheduled__2024-04-11T00:00:00+00:00 [running]> on host eaff2d74d54d
[2024-04-16T10:25:12.660+0000] {taskinstance.py:2644} INFO - Exporting env vars: AIRFLOW_CTX_DAG_OWNER='ika' AIRFLOW_CTX_DAG_ID='priority_one_number_one_dag_v1' AIRFLOW_CTX_TASK_ID='task_5' AIRFLOW_CTX_EXECUTION_DATE='2024-04-11T00:00:00+00:00' AIRFLOW_CTX_TRY_NUMBER='2' AIRFLOW_CTX_DAG_RUN_ID='scheduled__2024-04-11T00:00:00+00:00'
[2024-04-16T10:25:12.661+0000] {taskinstance.py:430} INFO - ::endgroup::
[2024-04-16T10:25:12.679+0000] {subprocess.py:63} INFO - Tmp dir root location: /tmp
[2024-04-16T10:25:12.681+0000] {subprocess.py:75} INFO - Running command: ['/usr/bin/bash', '-c', 'touch our_works/works.txt']
[2024-04-16T10:25:12.701+0000] {subprocess.py:86} INFO - Output:
[2024-04-16T10:25:12.709+0000] {subprocess.py:93} INFO - touch: cannot touch 'our_works/works.txt': No such file or directory
[2024-04-16T10:25:12.710+0000] {subprocess.py:97} INFO - Command exited with return code 1
[2024-04-16T10:25:12.712+0000] {taskinstance.py:441} INFO - ::group::Post task execution logs
[2024-04-16T10:25:12.730+0000] {taskinstance.py:2890} ERROR - Task failed with exception
Traceback (most recent call last):
  File "/home/airflow/.local/lib/python3.12/site-packages/airflow/models/taskinstance.py", line 465, in _execute_task
    result = _execute_callable(context=context, **execute_callable_kwargs)
             ^^^^^^^^^^^^^^^^^^^^^^^^^^^^^^^^^^^^^^^^^^^^^^^^^^^^^^^^^^^^^
  File "/home/airflow/.local/lib/python3.12/site-packages/airflow/models/taskinstance.py", line 432, in _execute_callable
    return execute_callable(context=context, **execute_callable_kwargs)
           ^^^^^^^^^^^^^^^^^^^^^^^^^^^^^^^^^^^^^^^^^^^^^^^^^^^^^^^^^^^^
  File "/home/airflow/.local/lib/python3.12/site-packages/airflow/models/baseoperator.py", line 400, in wrapper
    return func(self, *args, **kwargs)
           ^^^^^^^^^^^^^^^^^^^^^^^^^^^
  File "/home/airflow/.local/lib/python3.12/site-packages/airflow/operators/bash.py", line 243, in execute
    raise AirflowException(
airflow.exceptions.AirflowException: Bash command failed. The command returned a non-zero exit code 1.
[2024-04-16T10:25:12.740+0000] {taskinstance.py:1205} INFO - Marking task as UP_FOR_RETRY. dag_id=priority_one_number_one_dag_v1, task_id=task_5, execution_date=20240411T000000, start_date=20240416T102512, end_date=20240416T102512
[2024-04-16T10:25:12.761+0000] {standard_task_runner.py:110} ERROR - Failed to execute job 229 for task task_5 (Bash command failed. The command returned a non-zero exit code 1.; 196)
[2024-04-16T10:25:12.796+0000] {local_task_job_runner.py:240} INFO - Task exited with return code 1
[2024-04-16T10:25:12.832+0000] {taskinstance.py:3482} INFO - 0 downstream tasks scheduled from follow-on schedule check
[2024-04-16T10:25:12.838+0000] {local_task_job_runner.py:222} INFO - ::endgroup::
