[2024-04-16T10:27:54.855+0000] {local_task_job_runner.py:120} INFO - ::group::Pre task execution logs
[2024-04-16T10:27:54.986+0000] {taskinstance.py:2073} INFO - Dependencies all met for dep_context=non-requeueable deps ti=<TaskInstance: priority_one_number_one_dag_v1.task_5 scheduled__2024-04-14T00:00:00+00:00 [queued]>
[2024-04-16T10:27:55.228+0000] {taskinstance.py:2073} INFO - Dependencies all met for dep_context=requeueable deps ti=<TaskInstance: priority_one_number_one_dag_v1.task_5 scheduled__2024-04-14T00:00:00+00:00 [queued]>
[2024-04-16T10:27:55.239+0000] {taskinstance.py:2303} INFO - Starting attempt 2 of 6
[2024-04-16T10:27:55.382+0000] {taskinstance.py:2327} INFO - Executing <Task(BashOperator): task_5> on 2024-04-14 00:00:00+00:00
[2024-04-16T10:27:55.428+0000] {warnings.py:110} WARNING - /home/***/.local/lib/python3.12/site-packages/***/task/task_runner/standard_task_runner.py:61: DeprecationWarning: This process (pid=295) is multi-threaded, use of fork() may lead to deadlocks in the child.
  pid = os.fork()

[2024-04-16T10:27:55.437+0000] {standard_task_runner.py:63} INFO - Started process 301 to run task
[2024-04-16T10:27:55.654+0000] {standard_task_runner.py:90} INFO - Running: ['***', 'tasks', 'run', 'priority_one_number_one_dag_v1', 'task_5', 'scheduled__2024-04-14T00:00:00+00:00', '--job-id', '252', '--raw', '--subdir', 'DAGS_FOLDER/priority_one_number_one_dag.py', '--cfg-path', '/tmp/tmpscip3huh']
[2024-04-16T10:27:55.671+0000] {standard_task_runner.py:91} INFO - Job 252: Subtask task_5
[2024-04-16T10:27:56.045+0000] {task_command.py:426} INFO - Running <TaskInstance: priority_one_number_one_dag_v1.task_5 scheduled__2024-04-14T00:00:00+00:00 [running]> on host eaff2d74d54d
[2024-04-16T10:27:56.850+0000] {taskinstance.py:2644} INFO - Exporting env vars: AIRFLOW_CTX_DAG_OWNER='ika' AIRFLOW_CTX_DAG_ID='priority_one_number_one_dag_v1' AIRFLOW_CTX_TASK_ID='task_5' AIRFLOW_CTX_EXECUTION_DATE='2024-04-14T00:00:00+00:00' AIRFLOW_CTX_TRY_NUMBER='2' AIRFLOW_CTX_DAG_RUN_ID='scheduled__2024-04-14T00:00:00+00:00'
[2024-04-16T10:27:56.863+0000] {taskinstance.py:430} INFO - ::endgroup::
[2024-04-16T10:27:56.955+0000] {subprocess.py:63} INFO - Tmp dir root location: /tmp
[2024-04-16T10:27:56.967+0000] {subprocess.py:75} INFO - Running command: ['/usr/bin/bash', '-c', 'touch our_works/works.txt']
[2024-04-16T10:27:57.113+0000] {subprocess.py:86} INFO - Output:
[2024-04-16T10:27:57.290+0000] {subprocess.py:93} INFO - touch: cannot touch 'our_works/works.txt': No such file or directory
[2024-04-16T10:27:57.310+0000] {subprocess.py:97} INFO - Command exited with return code 1
[2024-04-16T10:27:57.313+0000] {taskinstance.py:441} INFO - ::group::Post task execution logs
[2024-04-16T10:27:57.524+0000] {taskinstance.py:2890} ERROR - Task failed with exception
Traceback (most recent call last):
  File "/home/airflow/.local/lib/python3.12/site-packages/airflow/models/taskinstance.py", line 465, in _execute_task
    result = _execute_callable(context=context, **execute_callable_kwargs)
             ^^^^^^^^^^^^^^^^^^^^^^^^^^^^^^^^^^^^^^^^^^^^^^^^^^^^^^^^^^^^^
  File "/home/airflow/.local/lib/python3.12/site-packages/airflow/models/taskinstance.py", line 432, in _execute_callable
    return execute_callable(context=context, **execute_callable_kwargs)
           ^^^^^^^^^^^^^^^^^^^^^^^^^^^^^^^^^^^^^^^^^^^^^^^^^^^^^^^^^^^^
  File "/home/airflow/.local/lib/python3.12/site-packages/airflow/models/baseoperator.py", line 400, in wrapper
    return func(self, *args, **kwargs)
           ^^^^^^^^^^^^^^^^^^^^^^^^^^^
  File "/home/airflow/.local/lib/python3.12/site-packages/airflow/operators/bash.py", line 243, in execute
    raise AirflowException(
airflow.exceptions.AirflowException: Bash command failed. The command returned a non-zero exit code 1.
[2024-04-16T10:27:57.673+0000] {taskinstance.py:1205} INFO - Marking task as UP_FOR_RETRY. dag_id=priority_one_number_one_dag_v1, task_id=task_5, execution_date=20240414T000000, start_date=20240416T102754, end_date=20240416T102757
[2024-04-16T10:27:57.876+0000] {standard_task_runner.py:110} ERROR - Failed to execute job 252 for task task_5 (Bash command failed. The command returned a non-zero exit code 1.; 301)
[2024-04-16T10:27:58.023+0000] {local_task_job_runner.py:240} INFO - Task exited with return code 1
[2024-04-16T10:27:58.593+0000] {taskinstance.py:3482} INFO - 0 downstream tasks scheduled from follow-on schedule check
[2024-04-16T10:27:58.621+0000] {local_task_job_runner.py:222} INFO - ::endgroup::
