[2024-04-16T10:25:54.336+0000] {task_context_logger.py:104} ERROR - Executor reports task instance <TaskInstance: priority_one_number_one_dag_v1.task_5 scheduled__2024-04-15T00:00:00+00:00 [queued]> finished (failed) although the task says it's queued. (Info: None) Was the task killed externally?
