[2024-04-19T08:29:49.464+0000] {task_context_logger.py:104} ERROR - Executor reports task instance <TaskInstance: data_ingest_exploration_dag_v1.extract_data_task scheduled__2024-04-16T00:00:00+00:00 [queued]> finished (failed) although the task says it's queued. (Info: None) Was the task killed externally?
