[2024-04-22T09:56:46.706+0000] {task_context_logger.py:104} ERROR - Executor reports task instance <TaskInstance: de_with_cloud_exploration_dag_v1.extract_data_task scheduled__2024-04-20T00:00:00+00:00 [queued]> finished (failed) although the task says it's queued. (Info: None) Was the task killed externally?
