[2024-04-16T10:35:27.546+0000] {local_task_job_runner.py:120} INFO - ::group::Pre task execution logs
[2024-04-16T10:35:27.589+0000] {taskinstance.py:2073} INFO - Dependencies all met for dep_context=non-requeueable deps ti=<TaskInstance: priority_one_number_one_dag_v1.task_4 scheduled__2024-04-12T00:00:00+00:00 [queued]>
[2024-04-16T10:35:27.600+0000] {taskinstance.py:2073} INFO - Dependencies all met for dep_context=requeueable deps ti=<TaskInstance: priority_one_number_one_dag_v1.task_4 scheduled__2024-04-12T00:00:00+00:00 [queued]>
[2024-04-16T10:35:27.601+0000] {taskinstance.py:2303} INFO - Starting attempt 4 of 6
[2024-04-16T10:35:27.621+0000] {taskinstance.py:2327} INFO - Executing <Task(BashOperator): task_4> on 2024-04-12 00:00:00+00:00
[2024-04-16T10:35:27.631+0000] {warnings.py:110} WARNING - /home/***/.local/lib/python3.12/site-packages/***/task/task_runner/standard_task_runner.py:61: DeprecationWarning: This process (pid=498) is multi-threaded, use of fork() may lead to deadlocks in the child.
  pid = os.fork()

[2024-04-16T10:35:27.633+0000] {standard_task_runner.py:63} INFO - Started process 499 to run task
[2024-04-16T10:35:27.633+0000] {standard_task_runner.py:90} INFO - Running: ['***', 'tasks', 'run', 'priority_one_number_one_dag_v1', 'task_4', 'scheduled__2024-04-12T00:00:00+00:00', '--job-id', '299', '--raw', '--subdir', 'DAGS_FOLDER/priority_one_number_one_dag.py', '--cfg-path', '/tmp/tmpe1y_vh8x']
[2024-04-16T10:35:27.636+0000] {standard_task_runner.py:91} INFO - Job 299: Subtask task_4
[2024-04-16T10:35:27.690+0000] {task_command.py:426} INFO - Running <TaskInstance: priority_one_number_one_dag_v1.task_4 scheduled__2024-04-12T00:00:00+00:00 [running]> on host eaff2d74d54d
[2024-04-16T10:35:27.775+0000] {taskinstance.py:2644} INFO - Exporting env vars: AIRFLOW_CTX_DAG_OWNER='ika' AIRFLOW_CTX_DAG_ID='priority_one_number_one_dag_v1' AIRFLOW_CTX_TASK_ID='task_4' AIRFLOW_CTX_EXECUTION_DATE='2024-04-12T00:00:00+00:00' AIRFLOW_CTX_TRY_NUMBER='4' AIRFLOW_CTX_DAG_RUN_ID='scheduled__2024-04-12T00:00:00+00:00'
[2024-04-16T10:35:27.777+0000] {taskinstance.py:430} INFO - ::endgroup::
[2024-04-16T10:35:27.811+0000] {subprocess.py:63} INFO - Tmp dir root location: /tmp
[2024-04-16T10:35:27.816+0000] {subprocess.py:75} INFO - Running command: ['/usr/bin/bash', '-c', 'touch about_us/about.txt']
[2024-04-16T10:35:27.832+0000] {subprocess.py:86} INFO - Output:
[2024-04-16T10:35:27.857+0000] {subprocess.py:93} INFO - touch: cannot touch 'about_us/about.txt': No such file or directory
[2024-04-16T10:35:27.858+0000] {subprocess.py:97} INFO - Command exited with return code 1
[2024-04-16T10:35:27.859+0000] {taskinstance.py:441} INFO - ::group::Post task execution logs
[2024-04-16T10:35:27.871+0000] {taskinstance.py:2890} ERROR - Task failed with exception
Traceback (most recent call last):
  File "/home/airflow/.local/lib/python3.12/site-packages/airflow/models/taskinstance.py", line 465, in _execute_task
    result = _execute_callable(context=context, **execute_callable_kwargs)
             ^^^^^^^^^^^^^^^^^^^^^^^^^^^^^^^^^^^^^^^^^^^^^^^^^^^^^^^^^^^^^
  File "/home/airflow/.local/lib/python3.12/site-packages/airflow/models/taskinstance.py", line 432, in _execute_callable
    return execute_callable(context=context, **execute_callable_kwargs)
           ^^^^^^^^^^^^^^^^^^^^^^^^^^^^^^^^^^^^^^^^^^^^^^^^^^^^^^^^^^^^
  File "/home/airflow/.local/lib/python3.12/site-packages/airflow/models/baseoperator.py", line 400, in wrapper
    return func(self, *args, **kwargs)
           ^^^^^^^^^^^^^^^^^^^^^^^^^^^
  File "/home/airflow/.local/lib/python3.12/site-packages/airflow/operators/bash.py", line 243, in execute
    raise AirflowException(
airflow.exceptions.AirflowException: Bash command failed. The command returned a non-zero exit code 1.
[2024-04-16T10:35:27.878+0000] {taskinstance.py:1205} INFO - Marking task as UP_FOR_RETRY. dag_id=priority_one_number_one_dag_v1, task_id=task_4, execution_date=20240412T000000, start_date=20240416T103527, end_date=20240416T103527
[2024-04-16T10:35:27.896+0000] {standard_task_runner.py:110} ERROR - Failed to execute job 299 for task task_4 (Bash command failed. The command returned a non-zero exit code 1.; 499)
[2024-04-16T10:35:27.930+0000] {local_task_job_runner.py:240} INFO - Task exited with return code 1
[2024-04-16T10:35:27.954+0000] {taskinstance.py:3482} INFO - 0 downstream tasks scheduled from follow-on schedule check
[2024-04-16T10:35:27.958+0000] {local_task_job_runner.py:222} INFO - ::endgroup::
