[2024-05-05T17:33:27.511+0000] {task_context_logger.py:104} ERROR - Executor reports task instance <TaskInstance: code_competence_2_dag_v1.load_data_task scheduled__2024-04-25T00:00:00+00:00 [queued]> finished (success) although the task says it's queued. (Info: None) Was the task killed externally?
