[2024-04-16T10:36:42.973+0000] {task_context_logger.py:104} ERROR - Executor reports task instance <TaskInstance: priority_one_number_two_dag_v1.generate_random_number scheduled__2024-03-07T00:00:00+00:00 [queued]> finished (failed) although the task says it's queued. (Info: None) Was the task killed externally?
