[2024-04-16T10:34:33.203+0000] {local_task_job_runner.py:120} INFO - ::group::Pre task execution logs
[2024-04-16T10:34:33.352+0000] {taskinstance.py:2073} INFO - Dependencies all met for dep_context=non-requeueable deps ti=<TaskInstance: priority_one_number_one_dag_v1.task_4 scheduled__2024-04-10T00:00:00+00:00 [queued]>
[2024-04-16T10:34:33.387+0000] {taskinstance.py:2073} INFO - Dependencies all met for dep_context=requeueable deps ti=<TaskInstance: priority_one_number_one_dag_v1.task_4 scheduled__2024-04-10T00:00:00+00:00 [queued]>
[2024-04-16T10:34:33.390+0000] {taskinstance.py:2303} INFO - Starting attempt 5 of 6
[2024-04-16T10:34:33.462+0000] {taskinstance.py:2327} INFO - Executing <Task(BashOperator): task_4> on 2024-04-10 00:00:00+00:00
[2024-04-16T10:34:33.515+0000] {warnings.py:110} WARNING - /home/***/.local/lib/python3.12/site-packages/***/task/task_runner/standard_task_runner.py:61: DeprecationWarning: This process (pid=445) is multi-threaded, use of fork() may lead to deadlocks in the child.
  pid = os.fork()

[2024-04-16T10:34:33.520+0000] {standard_task_runner.py:63} INFO - Started process 453 to run task
[2024-04-16T10:34:33.583+0000] {standard_task_runner.py:90} INFO - Running: ['***', 'tasks', 'run', 'priority_one_number_one_dag_v1', 'task_4', 'scheduled__2024-04-10T00:00:00+00:00', '--job-id', '289', '--raw', '--subdir', 'DAGS_FOLDER/priority_one_number_one_dag.py', '--cfg-path', '/tmp/tmp87flg044']
[2024-04-16T10:34:33.604+0000] {standard_task_runner.py:91} INFO - Job 289: Subtask task_4
[2024-04-16T10:34:34.056+0000] {task_command.py:426} INFO - Running <TaskInstance: priority_one_number_one_dag_v1.task_4 scheduled__2024-04-10T00:00:00+00:00 [running]> on host eaff2d74d54d
[2024-04-16T10:34:34.535+0000] {taskinstance.py:2644} INFO - Exporting env vars: AIRFLOW_CTX_DAG_OWNER='ika' AIRFLOW_CTX_DAG_ID='priority_one_number_one_dag_v1' AIRFLOW_CTX_TASK_ID='task_4' AIRFLOW_CTX_EXECUTION_DATE='2024-04-10T00:00:00+00:00' AIRFLOW_CTX_TRY_NUMBER='5' AIRFLOW_CTX_DAG_RUN_ID='scheduled__2024-04-10T00:00:00+00:00'
[2024-04-16T10:34:34.559+0000] {taskinstance.py:430} INFO - ::endgroup::
[2024-04-16T10:34:34.758+0000] {subprocess.py:63} INFO - Tmp dir root location: /tmp
[2024-04-16T10:34:34.821+0000] {subprocess.py:75} INFO - Running command: ['/usr/bin/bash', '-c', 'touch about_us/about.txt']
[2024-04-16T10:34:34.880+0000] {subprocess.py:86} INFO - Output:
[2024-04-16T10:34:35.012+0000] {subprocess.py:93} INFO - touch: cannot touch 'about_us/about.txt': No such file or directory
[2024-04-16T10:34:35.014+0000] {subprocess.py:97} INFO - Command exited with return code 1
[2024-04-16T10:34:35.030+0000] {taskinstance.py:441} INFO - ::group::Post task execution logs
[2024-04-16T10:34:35.074+0000] {taskinstance.py:2890} ERROR - Task failed with exception
Traceback (most recent call last):
  File "/home/airflow/.local/lib/python3.12/site-packages/airflow/models/taskinstance.py", line 465, in _execute_task
    result = _execute_callable(context=context, **execute_callable_kwargs)
             ^^^^^^^^^^^^^^^^^^^^^^^^^^^^^^^^^^^^^^^^^^^^^^^^^^^^^^^^^^^^^
  File "/home/airflow/.local/lib/python3.12/site-packages/airflow/models/taskinstance.py", line 432, in _execute_callable
    return execute_callable(context=context, **execute_callable_kwargs)
           ^^^^^^^^^^^^^^^^^^^^^^^^^^^^^^^^^^^^^^^^^^^^^^^^^^^^^^^^^^^^
  File "/home/airflow/.local/lib/python3.12/site-packages/airflow/models/baseoperator.py", line 400, in wrapper
    return func(self, *args, **kwargs)
           ^^^^^^^^^^^^^^^^^^^^^^^^^^^
  File "/home/airflow/.local/lib/python3.12/site-packages/airflow/operators/bash.py", line 243, in execute
    raise AirflowException(
airflow.exceptions.AirflowException: Bash command failed. The command returned a non-zero exit code 1.
[2024-04-16T10:34:35.092+0000] {taskinstance.py:1205} INFO - Marking task as UP_FOR_RETRY. dag_id=priority_one_number_one_dag_v1, task_id=task_4, execution_date=20240410T000000, start_date=20240416T103433, end_date=20240416T103435
[2024-04-16T10:34:35.198+0000] {standard_task_runner.py:110} ERROR - Failed to execute job 289 for task task_4 (Bash command failed. The command returned a non-zero exit code 1.; 453)
[2024-04-16T10:34:35.325+0000] {local_task_job_runner.py:240} INFO - Task exited with return code 1
[2024-04-16T10:34:35.383+0000] {taskinstance.py:3482} INFO - 0 downstream tasks scheduled from follow-on schedule check
[2024-04-16T10:34:35.394+0000] {local_task_job_runner.py:222} INFO - ::endgroup::
